Workbook
Name MonthSlicer: #N/A
Name SupplierSlicer: #N/A

Sheet 2026 Metrics
A1: Admin Fee Cost Avoidance
A2: 309967.52 | E2: Percentage of Reduction/Increase | I2: #REF!
A4: Total Cost Savings | E4: Total Shipping Costs | I4: Total Inbound Shipments | M4: Cost Per Unit (CPU) | Q4: Cost Per Shipment
A5: 0 | E5: 939726.78 | I5: 819 | M5: 1.4847387 | Q5: 1147.4075
A7: Avg Cost Per Pallet | E7: Avg Cost Per Mile | I7: Total Cargo Value | M7: Cost as % of Cargo Value | Q7: Total Units Shipped
A8: 361.8509 | E8: 1.101924 | I8: 61993503 | M8: 0.015158472 | Q8: 632924
A13: VAR Total Cost Savings | E13: VAR Total Shipping Costs | I13: Total Inbound Shipments | M13: VAR Cost Per Unit (CPU) | Q13: Cost Per Shipment
A14: 0 | E14: 0 | I14: 819 | M14: 0 | Q14: #REF!
A16: VAR Avg Cost Per Pallet | E16: VAR Avg Cost Per Mile | I16: Total Cargo Value | M16: VAR Cost as % of Cargo Value
A17: 0 | E17: 0 | I17: 61993503 | M17: #REF!
E19: Percentage of Increase | I19: #REF!
F25: Vendor Managed Inbound to RAD | I25: GTL Managed Inbound to RAD
B26: Year | C26: Supplier | D26: Ship Volume | E26: Total Units | F26: Total Cost | G26: Average Cost / Shipment | H26: CPU | I26: Total Cost | J26: Average Cost / Shipment | K26: CPU | L26: Avg Cost Variance ($) | M26: Cost Variance (%) | N26: CPU Variance ($) | O26: CPU Variance (%)
B27: 2024 | C27: Denali (Parcel) | D27: 42357 | E27: 188232 | F27: 839515.74 | G27: 19.82 | H27: 4.46 | I27: 383330.85 | J27: 9.05 | K27: 2.04 | L27: -10.77 | M27: -0.5434 | N27: -2.42 | O27: -0.5434
C28: Scheider (Freight) | D28: 19 | E28: 2023 | F28: 46156.71 | G28: 2429.3 | H28: 22.82 | I28: 21613.23 | J28: 1137.54 | K28: 10.68 | L28: -1291.76 | M28: -0.5317 | N28: -12.13 | O28: -0.5317
C29: Total | D29: 42376 | E29: 190255 | F29: 885672.45 | G29: 20.9 | H29: 4.66 | I29: 404944.08 | J29: 9.56 | K29: 2.13 | L29: -11.34 | M29: -0.5428 | N29: -2.53 | O29: -0.5428
B30: 2025 | C30: DENALI | D30: 565 | E30: 618951 | F30: 1186703 | G30: 2100.3592 | H30: 1.917281 | I30: 774806.76 | J30: 1371.3394 | K30: 1.2518063 | L30: -729.01984 | M30: -0.34709293 | N30: -0.66547466 | O30: -0.34709293
C31: SCHNEIDER ELECTRIC | D31: 220 | E31: 2207 | F31: 190001.64 | G31: 863.64383 | H31: 86.090459 | I31: 88952.08 | J31: 404.32764 | K31: 40.304522 | L31: -459.31619 | M31: -0.53183521 | N31: -45.785937 | O31: -0.53183521
C33: Total | D33: 785 | E33: 621158 | F33: 1376704.6 | G33: 1753.7638 | H33: 2.2163517 | I33: 863758.84 | J33: 1100.3297 | K33: 1.3905622 | L33: -653.4341 | M33: -0.37258956 | N33: -0.82578953 | O33: -0.37258956

Sheet 2026 IB Shipments
A1: PROGRAM | B1: PROJECT TYPE | C1: ORIGIN WHID | D1: ORIGIN STATE | E1: DEST WHID | F1: DEST STATE / PROV | G1: BOL# | H1: NBD | I1: ESCALATED? | J1: PRO/TRACKING | K1: PICKUP DATE | L1: OT P/U? | M1: ETA DATE | N1: DLV DATE | O1: Total Transit Time (# of Days) | P1: OT Delv? | Q1: Issues? | S1: DLV MILES | T1: REF # | U1: PALLETS | V1: UNITS | W1: WGT (LBS | X1: MODE | Y1: CARRIER ACCOUNT | Z1: CARRIER | AA1: SERVICE LEVEL | AB1: SERVICE COST | AC1: QUOTED COST FROM SUPPLIER | AD1: COST SAVINGS | AE1: CARGO VALUE | AF1: Cost per Skid | AG1: Cost per Unit | AH1: Cost per Mile | AI1: Cost Center | AJ1: GL String / PO #
A2: Inbound | B2: Vendor to Site | C2: SCHNEIDER ELECTRIC | D2: PA | E2: TTN2 | F2: NJ | G2: RXO6225764 | H2: 46030 | I2: No | J2: 138875133 | K2: 46027 | L2: Yes | M2: 46045 | N2: 46045 | O2: =NETWORKDAYS.INTL(K2,N2,1,$AM$2:$AM$10)-1 -> 13 | P2: Yes | Q2: Yes | R2: Awaiting delivery appt; site contacted twice to make delivery appt. Delivery appt finally made on 1/22. | S2: 140 | T2: 2D-19833922 | U2: 1 | V2: 7 | W2: 579 | X2: LTL | Y2: RXO | Z2: XPO LOGISTICS | AA2: GROUND | AB2: 192.32 | AC2: =IF(C2="DENALI", AB2*0.495, IF(C2="SCHNEIDER ELECTRIC", AB2*1.136, IF(C2="WWT", AB2*1.2, AC2)))+AB2 -> 410.79552 | AD2: =AC2-AB2 -> 218.47552 | AE2: 3342.43 | AF2: =AB2/U2 -> 192.32 | AG2: =AB2/V2 -> 27.474286 | AH2: =AB2/S2 -> 1.3737143 | AI2: 1085 | AJ2: 2D-20454099 | AM2: 46023
A3: Inbound | B3: Vendor to Site | C3: SCHNEIDER ELECTRIC | D3: CA | E3: AUS3 | F3: TX | G3: RXO6227023 | H3: 46031 | I3: No | J3: 138875365 | K3: 46027 | L3: Yes | M3: 46030 | N3: 46030 | O3: =NETWORKDAYS.INTL(K3,N3,1,$AM$2:$AM$10)-1 -> 3 | P3: Yes | Q3: No | R3: N/A | S3: 1352 | T3: 2D-19819566 | U3: 1 | V3: 2 | W3: 339 | X3: LTL | Y3: RXO | Z3: XPO LOGISTICS | AA3: GROUND | AB3: 279.46 | AC3: =IF(C3="DENALI", AB3*0.495, IF(C3="SCHNEIDER ELECTRIC", AB3*1.136, IF(C3="WWT", AB3*1.2, AC3)))+AB3 -> 596.92656 | AD3: =AC3-AB3 -> 317.46656 | AE3: 7917.38 | AF3: =AB3/U3 -> 279.46 | AG3: =AB3/V3 -> 139.73 | AH3: =AB3/S3 -> 0.20670118 | AI3: 1290 | AJ3: 2D-18027285 | AM3: 46041
A4: Inbound | B4: Vendor to Site | C4: DENALI | D4: WA | E4: SEA109 | F4: WA | G4: RXO6254027 | H4: 46028 | I4: No | J4: 59738987359 | K4: 46028 | L4: Yes | M4: 46031 | N4: 46030 | O4: =NETWORKDAYS.INTL(K4,N4,1,$AM$2:$AM$10)-1 -> 2 | P4: Yes | Q4: No | R4: Driver told site doesn't receive freight; onsite POC provided correct dock and phone number for redelivery on 1/8 | S4: 29 | T4: 2D-19224048 | U4: 2 | V4: 72 | W4: 720 | X4: LTL | Y4: RXO | Z4: OLD DOMINION | AA4: GROUND | AB4: 664.23 | AC4: =IF(C4="DENALI", AB4*0.495, IF(C4="SCHNEIDER ELECTRIC", AB4*1.136, IF(C4="WWT", AB4*1.2, AC4)))+AB4 -> 993.02385 | AD4: =AC4-AB4 -> 328.79385 | AE4: 70359.12 | AF4: =AB4/U4 -> 332.115 | AG4: =AB4/V4 -> 9.2254167 | AH4: =AB4/S4 -> 22.904483 | AI4: 7812 | AJ4: 2D-20412467 | AM4: 46167
A5: Inbound | B5: Vendor to Site | C5: DENALI | D5: WA | E5: TPA8 | F5: FL | G5: 21029093 | H5: 46034 | I5: No | J5: RXONC20O05XEV56A26 | K5: 46029 | L5: Yes | M5: 46034 | N5: 46035 | O5: =NETWORKDAYS.INTL(K5,N5,1,$AM$2:$AM$10)-1 -> 4 | P5: Yes | Q5: No | R5: Driver had family emergency on 1/12; RXO found another driver to deliver on 1/13 | S5: 3097 | T5: 2D-19570095 | U5: 14 | V5: 14 | W5: 9940 | X5: FTL | Y5: RXO | Z5: YLD TRANSPORT INC | AA5: GROUND | AB5: 6901.19 | AC5: =IF(C5="DENALI", AB5*0.495, IF(C5="SCHNEIDER ELECTRIC", AB5*1.136, IF(C5="WWT", AB5*1.2, AC5)))+AB5 -> 10317.279 | AD5: =AC5-AB5 -> 3416.089 | AE5: 115387.44 | AF5: =AB5/U5 -> 492.94214 | AG5: =AB5/V5 -> 492.94214 | AH5: =AB5/S5 -> 2.2283468 | AI5: 1173 | AJ5: 2D-19973674 | AM5: 46206
A6: Inbound | B6: Vendor to Site | C6: SCHNEIDER ELECTRIC | D6: CA | E6: IAH5 | F6: TX | G6: RXO6266501 | H6: 46034 | I6: No | J6: 178325114 | K6: 46029 | L6: Yes | M6: 46034 | N6: 46034 | O6: =NETWORKDAYS.INTL(K6,N6,1,$AM$2:$AM$10)-1 -> 3 | P6: Yes | Q6: No | R6: N/A | S6: 1528 | T6: 2D-19878523 | U6: 1 | V6: 4 | W6: 348 | X6: LTL | Y6: RXO | Z6: XPO LOGISTICS | AA6: GROUND | AB6: 236.14 | AC6: =IF(C6="DENALI", AB6*0.495, IF(C6="SCHNEIDER ELECTRIC", AB6*1.136, IF(C6="WWT", AB6*1.2, AC6)))+AB6 -> 504.39504 | AD6: =AC6-AB6 -> 268.25504 | AE6: 1909.96 | AF6: =AB6/U6 -> 236.14 | AG6: =AB6/V6 -> 59.035 | AH6: =AB6/S6 -> 0.15454188 | AI6: 1173 | AJ6: 2D-18027278 | AM6: 46272
A7: Inbound | B7: Vendor to Site | C7: SCHNEIDER ELECTRIC | D7: CA | E7: AUS3 | F7: TX | G7: RXO6266361 | H7: 46034 | I7: No | J7: 178325125 | K7: 46029 | L7: Yes | M7: 46034 | N7: 46034 | O7: =NETWORKDAYS.INTL(K7,N7,1,$AM$2:$AM$10)-1 -> 3 | P7: Yes | Q7: No | R7: N/A | S7: 1352 | T7: 2D-19869169 | U7: 1 | V7: 8 | W7: 656 | X7: LTL | Y7: RXO | Z7: XPO LOGISTICS | AA7: GROUND | AB7: 279.46 | AC7: =IF(C7="DENALI", AB7*0.495, IF(C7="SCHNEIDER ELECTRIC", AB7*1.136, IF(C7="WWT", AB7*1.2, AC7)))+AB7 -> 596.92656 | AD7: =AC7-AB7 -> 317.46656 | AE7: 3819.92 | AF7: =AB7/U7 -> 279.46 | AG7: =AB7/V7 -> 34.9325 | AH7: =AB7/S7 -> 0.20670118 | AI7: 1290 | AJ7: 2D-18027285 | AM7: 46352
A8: Inbound | B8: Vendor to Site | C8: DENALI | D8: WA | E8: SJC8 | F8: CA | G8: 21041136 | H8: 46031 | I8: No | J8: RXONC20OTEC2TY7A26 | K8: 46029 | L8: Yes | M8: 46031 | N8: 46031 | O8: =NETWORKDAYS.INTL(K8,N8,1,$AM$2:$AM$10)-1 -> 2 | P8: Yes | Q8: No | R8: N/A | S8: 908 | T8: 2D-19276008 | U8: 12 | V8: 2073 | W8: 10200 | X8: FTL | Y8: RXO | Z8: G T LOGISTICS | AA8: GROUND | AB8: 1794 | AC8: =IF(C8="DENALI", AB8*0.495, IF(C8="SCHNEIDER ELECTRIC", AB8*1.136, IF(C8="WWT", AB8*1.2, AC8)))+AB8 -> 2682.03 | AD8: =AC8-AB8 -> 888.03 | AE8: 1121244.9 | AF8: =AB8/U8 -> 149.5 | AG8: =AB8/V8 -> 0.86541245 | AH8: =AB8/S8 -> 1.9757709 | AI8: 1290 | AJ8: 2D-19966575 | AM8: 46353
A9: Inbound | B9: Vendor to Site | C9: SCHNEIDER ELECTRIC | D9: PA | E9: OWD9 | F9: MA | G9: RXO6288660 | H9: 46034 | I9: No | J9: 138884045 | K9: 46031 | L9: Yes | M9: 46034 | N9: 46034 | O9: =NETWORKDAYS.INTL(K9,N9,1,$AM$2:$AM$10)-1 -> 1 | P9: Yes | Q9: No | R9: N/A | S9: 393 | T9: 2D-19916799 | U9: 1 | V9: 6 | W9: 464 | X9: LTL | Y9: RXO | Z9: XPO LOGISTICS | AA9: GROUND | AB9: 216.91 | AC9: =IF(C9="DENALI", AB9*0.495, IF(C9="SCHNEIDER ELECTRIC", AB9*1.136, IF(C9="WWT", AB9*1.2, AC9)))+AB9 -> 463.31976 | AD9: =AC9-AB9 -> 246.40976 | AE9: 2646.47 | AF9: =AB9/U9 -> 216.91 | AG9: =AB9/V9 -> 36.151667 | AH9: =AB9/S9 -> 0.55193384 | AI9: 1173 | AJ9: 2D-18027278 | AM9: 46380
A10: Inbound | B10: Vendor to Site | C10: SCHNEIDER ELECTRIC | D10: CA | E10: LGB3 | F10: CA | G10: RXO6299350 | H10: 46035 | I10: No | J10: 138886554 | K10: 46034 | L10: No | M10: 46036 | N10: 46036 | O10: =NETWORKDAYS.INTL(K10,N10,1,$AM$2:$AM$10)-1 -> 2 | P10: Yes | Q10: No | R10: Pickup originally scheduled for 1/9 | S10: 35 | T10: 2D-19920350 | U10: 1 | V10: 3 | W10: 271 | X10: LTL | Y10: RXO | Z10: XPO LOGISTICS | AA10: GROUND | AB10: 179.14 | AC10: =IF(C10="DENALI", AB10*0.495, IF(C10="SCHNEIDER ELECTRIC", AB10*1.136, IF(C10="WWT", AB10*1.2, AC10)))+AB10 -> 382.64304 | AD10: =AC10-AB10 -> 203.50304 | AE10: 1432.47 | AF10: =AB10/U10 -> 179.14 | AG10: =AB10/V10 -> 59.713333 | AH10: =AB10/S10 -> 5.1182857 | AI10: 1290 | AJ10: 2D-18027285 | AM10: 46381
A11: Inbound | B11: Vendor to RAD | C11: DENALI | D11: WA | E11: RAD1 | F11: TN | G11: RXO6343885 | H11: 46041 | I11: No | J11: 138892246 | K11: 46036 | L11: Yes | M11: 46043 | N11: 46043 | O11: =NETWORKDAYS.INTL(K11,N11,1,$AM$2:$AM$10)-1 -> 4 | P11: Yes | Q11: No | R11: Awaiting delivery appt; appt scheduled for 1/21 | S11: 2403 | T11: 2D-19010710 | U11: 2 | V11: 180 | W11: 720 | X11: LTL | Y11: RXO | Z11: XPO LOGISTICS | AA11: GROUND | AB11: 620.72 | AC11: =IF(C11="DENALI", AB11*0.495, IF(C11="SCHNEIDER ELECTRIC", AB11*1.136, IF(C11="WWT", AB11*1.2, AC11)))+AB11 -> 927.9764 | AD11: =AC11-AB11 -> 307.2564 | AE11: 15632.08 | AF11: =AB11/U11 -> 310.36 | AG11: =AB11/V11 -> 3.4484444 | AH11: =AB11/S11 -> 0.25831045 | AI11: 1060 | AJ11: 2D-20053262
A12: Inbound | B12: Vendor to Site | C12: SCHNEIDER ELECTRIC | D12: CA | E12: DPD4 | F12: OR | G12: RXO6371067 | H12: 46044 | I12: No | J12: 2938031892 | K12: 46038 | L12: Yes | M12: 46043 | N12: 46043 | O12: =NETWORKDAYS.INTL(K12,N12,1,$AM$2:$AM$10)-1 -> 2 | P12: Yes | Q12: No | R12: N/A | S12: 985 | T12: 2D-20005187 | U12: 1 | V12: 4 | W12: 195 | X12: LTL | Y12: RXO | Z12: ESTES EXPRESS LINES | AA12: GROUND | AB12: 280.22 | AC12: =IF(C12="DENALI", AB12*0.495, IF(C12="SCHNEIDER ELECTRIC", AB12*1.136, IF(C12="WWT", AB12*1.2, AC12)))+AB12 -> 598.54992 | AD12: =AC12-AB12 -> 318.32992 | AE12: 2169.88 | AF12: =AB12/U12 -> 280.22 | AG12: =AB12/V12 -> 70.055 | AH12: =AB12/S12 -> 0.28448731 | AI12: 1172 | AJ12: 2D-18027285
A13: Inbound | B13: Vendor to Site | C13: SCHNEIDER ELECTRIC | D13: CA | E13: STX4 | F13: TX | G13: RXO6371500 | H13: 46044 | I13: No | J13: 121495229100 | K13: 46038 | L13: Yes | M13: 46043 | N13: 46043 | O13: =NETWORKDAYS.INTL(K13,N13,1,$AM$2:$AM$10)-1 -> 2 | P13: Yes | Q13: No | R13: N/A | S13: 1535 | T13: 2D-20023807 | U13: 1 | V13: 5 | W13: 234 | X13: LTL | Y13: RXO | Z13: SAIA MOTOR FREIGHT LINES | AA13: GROUND | AB13: 383.12 | AC13: =IF(C13="DENALI", AB13*0.495, IF(C13="SCHNEIDER ELECTRIC", AB13*1.136, IF(C13="WWT", AB13*1.2, AC13)))+AB13 -> 818.34432 | AD13: =AC13-AB13 -> 435.22432 | AE13: 1414 | AF13: =AB13/U13 -> 383.12 | AG13: =AB13/V13 -> 76.624 | AH13: =AB13/S13 -> 0.24958958 | AI13: 1060 | AJ13: 2D-18027285
A14: Inbound | B14: Vendor to Site | C14: SCHNEIDER ELECTRIC | D14: CA | E14: DVL4 | F14: NV | G14: RXO6371780 | H14: 46044 | I14: No | J14: 138896601 | K14: 46038 | L14: Yes | M14: 46042 | N14: 46042 | O14: =NETWORKDAYS.INTL(K14,N14,1,$AM$2:$AM$10)-1 -> 1 | P14: Yes | Q14: No | R14: N/A | S14: 229 | T14: 2D-20035279 | U14: 1 | V14: 8 | W14: 349 | X14: LTL | Y14: RXO | Z14: XPO LOGISTICS | AA14: GROUND | AB14: 235.76 | AC14: =IF(C14="DENALI", AB14*0.495, IF(C14="SCHNEIDER ELECTRIC", AB14*1.136, IF(C14="WWT", AB14*1.2, AC14)))+AB14 -> 503.58336 | AD14: =AC14-AB14 -> 267.82336 | AE14: 2262.4 | AF14: =AB14/U14 -> 235.76 | AG14: =AB14/V14 -> 29.47 | AH14: =AB14/S14 -> 1.0295197 | AI14: 1172 | AJ14: 2D-18027285
A15: Inbound | B15: Vendor to Site | C15: SCHNEIDER ELECTRIC | D15: CA | E15: DLV7 | F15: NV | G15: RXO6372046 | H15: 46044 | I15: No | J15: 138896634 | K15: 46038 | L15: Yes | M15: 46042 | N15: 46042 | O15: =NETWORKDAYS.INTL(K15,N15,1,$AM$2:$AM$10)-1 -> 1 | P15: Yes | Q15: No | R15: N/A | S15: 243 | T15: 2D-20035280 | U15: 1 | V15: 6 | W15: 272 | X15: LTL | Y15: RXO | Z15: XPO LOGISTICS | AA15: GROUND | AB15: 235.76 | AC15: =IF(C15="DENALI", AB15*0.495, IF(C15="SCHNEIDER ELECTRIC", AB15*1.136, IF(C15="WWT", AB15*1.2, AC15)))+AB15 -> 503.58336 | AD15: =AC15-AB15 -> 267.82336 | AE15: 1696.8 | AF15: =AB15/U15 -> 235.76 | AG15: =AB15/V15 -> 39.293333 | AH15: =AB15/S15 -> 0.97020576 | AI15: 1172 | AJ15: 2D-18027285
A16: Inbound | B16: Vendor to Site | C16: SCHNEIDER ELECTRIC | D16: CA | E16: DLV2 | F16: NV | G16: RXO6372233 | H16: 46044 | I16: No | J16: 138896726 | K16: 46038 | L16: Yes | M16: 46042 | N16: 46042 | O16: =NETWORKDAYS.INTL(K16,N16,1,$AM$2:$AM$10)-1 -> 1 | P16: Yes | Q16: No | R16: N/A | S16: 247 | T16: 2D-20035262 | U16: 1 | V16: 10 | W16: 427 | X16: LTL | Y16: RXO | Z16: XPO LOGISTICS | AA16: GROUND | AB16: 235.76 | AC16: =IF(C16="DENALI", AB16*0.495, IF(C16="SCHNEIDER ELECTRIC", AB16*1.136, IF(C16="WWT", AB16*1.2, AC16)))+AB16 -> 503.58336 | AD16: =AC16-AB16 -> 267.82336 | AE16: 3347.34 | AF16: =AB16/U16 -> 235.76 | AG16: =AB16/V16 -> 23.576 | AH16: =AB16/S16 -> 0.95449393 | AI16: 1172 | AJ16: 2D-18027285
A17: Inbound | B17: Vendor to Site | C17: SCHNEIDER ELECTRIC | D17: CA | E17: HLV1 | F17: NV | G17: RXO6372682 | H17: 46044 | I17: No | J17: 138896811 | K17: 46042 | L17: Yes | M17: 46043 | N17: 46043 | O17: =NETWORKDAYS.INTL(K17,N17,1,$AM$2:$AM$10)-1 -> 1 | P17: Yes | Q17: No | R17: N/A | S17: 248 | T17: 2D-20035281 | U17: 1 | V17: 4 | W17: 195 | X17: LTL | Y17: RXO | Z17: XPO LOGISTICS | AA17: GROUND | AB17: 235.76 | AC17: =IF(C17="DENALI", AB17*0.495, IF(C17="SCHNEIDER ELECTRIC", AB17*1.136, IF(C17="WWT", AB17*1.2, AC17)))+AB17 -> 503.58336 | AD17: =AC17-AB17 -> 267.82336 | AE17: 1131.2 | AF17: =AB17/U17 -> 235.76 | AG17: =AB17/V17 -> 58.94 | AH17: =AB17/S17 -> 0.95064516 | AI17: 1067 | AJ17: 2D-18027285
A18: Inbound | B18: Vendor to RAD | C18: SCHNEIDER ELECTRIC | D18: PA | E18: RAD1 | F18: TN | G18: RXO6391057 | H18: 46048 | I18: No | J18: 138898841 | K18: 46042 | L18: Yes | M18: 46052 | N18: 46052 | O18: =NETWORKDAYS.INTL(K18,N18,1,$AM$2:$AM$10)-1 -> 8 | P18: No | Q18: Yes | R18: Carrier arrived after 4pm on 1/23, receive team not available to download. New appt scheduled for 1/30 at 12pm. | S18: 735 | T18: 2D-20004237 | U18: 3 | V18: 15 | W18: 1527 | X18: LTL | Y18: RXO | Z18: XPO LOGISTICS | AA18: GROUND | AB18: 719.02 | AC18: =IF(C18="DENALI", AB18*0.495, IF(C18="SCHNEIDER ELECTRIC", AB18*1.136, IF(C18="WWT", AB18*1.2, AC18)))+AB18 -> 1535.8267 | AD18: =AC18-AB18 -> 816.80672 | AE18: 37950 | AF18: =AB18/U18 -> 239.67333 | AG18: =AB18/V18 -> 47.934667 | AH18: =AB18/S18 -> 0.9782585 | AI18: 1084 | AJ18: 2D-18027278
A19: Inbound | B19: Vendor to RAD | C19: SCHNEIDER ELECTRIC | D19: PA | E19: RAD1 | F19: TN | G19: RXO6395594 | H19: 46048 | I19: No | J19: 0248881230 | K19: 46043 | L19: No | M19: 46049 | N19: 46058 | O19: =NETWORKDAYS.INTL(K19,N19,1,$AM$2:$AM$10)-1 -> 11 | P19: No | Q19: Yes | R19: Pickup originally scheduled for 1/20; delivery appt made for 1/28. Carrier did not show up. Delivery appt made for 2/3 | S19: 735 | T19: 2D-20032788 | U19: 1 | V19: 4 | W19: 438 | X19: LTL | Y19: RXO | Z19: ESTES EXPRESS LINES | AA19: GROUND | AB19: 213.85 | AC19: =IF(C19="DENALI", AB19*0.495, IF(C19="SCHNEIDER ELECTRIC", AB19*1.136, IF(C19="WWT", AB19*1.2, AC19)))+AB19 -> 456.7836 | AD19: =AC19-AB19 -> 242.9336 | AE19: 11670.82 | AF19: =AB19/U19 -> 213.85 | AG19: =AB19/V19 -> 53.4625 | AH19: =AB19/S19 -> 0.29095238 | AI19: 1084 | AJ19: 2D-18027278
A20: Inbound | B20: Vendor to Site | C20: SCHNEIDER ELECTRIC | D20: CA | E20: SLC1 | F20: UT | G20: RXO6397159 | H20: 46048 | I20: No | J20: 2930081672 | K20: 46042 | L20: Yes | M20: 46044 | N20: 46044 | O20: =NETWORKDAYS.INTL(K20,N20,1,$AM$2:$AM$10)-1 -> 2 | P20: Yes | Q20: No | R20: N/A | S20: 661 | T20: 2D-20048918 | U20: 1 | V20: 5 | W20: 425 | X20: LTL | Y20: RXO | Z20: ESTES EXPRESS LINES | AA20: GROUND | AB20: 247.9 | AC20: =IF(C20="DENALI", AB20*0.495, IF(C20="SCHNEIDER ELECTRIC", AB20*1.136, IF(C20="WWT", AB20*1.2, AC20)))+AB20 -> 529.5144 | AD20: =AC20-AB20 -> 281.6144 | AE20: 2387.45 | AF20: =AB20/U20 -> 247.9 | AG20: =AB20/V20 -> 49.58 | AH20: =AB20/S20 -> 0.37503782 | AI20: 1290 | AJ20: 2D-18027285
A21: Inbound | B21: Vendor to Site | C21: DENALI | D21: WA | E21: HOU6 | F21: TX | G21: RXO6396248 | H21: 46049 | I21: No | J21: 138899902 | K21: 46042 | L21: Yes | M21: 46051 | N21: 46051 | O21: =NETWORKDAYS.INTL(K21,N21,1,$AM$2:$AM$10)-1 -> 7 | P21: Yes | Q21: No | R21: N/A | S21: 2354 | T21: 2D-18704369 | U21: 1 | V21: 1 | W21: 348 | X21: LTL | Y21: RXO | Z21: XPO LOGISTICS | AA21: GROUND | AB21: 231.38 | AC21: =IF(C21="DENALI", AB21*0.495, IF(C21="SCHNEIDER ELECTRIC", AB21*1.136, IF(C21="WWT", AB21*1.2, AC21)))+AB21 -> 345.9131 | AD21: =AC21-AB21 -> 114.5331 | AE21: 2063.11 | AF21: =AB21/U21 -> 231.38 | AG21: =AB21/V21 -> 231.38 | AH21: =AB21/S21 -> 0.098292268 | AI21: 7812 | AJ21: 2D-18027285
A22: Inbound | B22: Vendor to RAD | C22: DENALI | D22: WA | E22: RAD1 | F22: TN | G22: RXO6396517 | H22: 46048 | I22: No | J22: 138899994 | K22: 46042 | L22: Yes | M22: 46059 | N22: 46059 | O22: =NETWORKDAYS.INTL(K22,N22,1,$AM$2:$AM$10)-1 -> 13 | P22: Yes | Q22: No | R22: Inclement weather near date of delivery; delivery appt scheduled for 2/6 | S22: 2403 | T22: 2D-20046415 | U22: 1 | V22: 1630 | W22: 670 | X22: LTL | Y22: RXO | Z22: XPO LOGISTICS | AA22: GROUND | AB22: 376.16 | AC22: =IF(C22="DENALI", AB22*0.495, IF(C22="SCHNEIDER ELECTRIC", AB22*1.136, IF(C22="WWT", AB22*1.2, AC22)))+AB22 -> 562.3592 | AD22: =AC22-AB22 -> 186.1992 | AE22: 116447.2 | AF22: =AB22/U22 -> 376.16 | AG22: =AB22/V22 -> 0.23077301 | AH22: =AB22/S22 -> 0.15653766 | AI22: 1172 | AJ22: 2D-18027278
A23: Inbound | B23: Vendor to Site | C23: DENALI | D23: WA | E23: SWA5 | F23: WA | G23: RXO6410867 | H23: 46048 | I23: No | J23: 2358063475 | K23: 46044 | L23: Yes | M23: 46045 | N23: 46045 | O23: =NETWORKDAYS.INTL(K23,N23,1,$AM$2:$AM$10)-1 -> 1 | P23: Yes | Q23: No | R23: N/A | S23: 37 | T23: 2D-19437804 | U23: 6 | V23: 154 | W23: 5100 | X23: LTL | Y23: RXO | Z23: ESTES EXPRESS LINES | AA23: GROUND | AB23: 443.12 | AC23: =IF(C23="DENALI", AB23*0.495, IF(C23="SCHNEIDER ELECTRIC", AB23*1.136, IF(C23="WWT", AB23*1.2, AC23)))+AB23 -> 662.4644 | AD23: =AC23-AB23 -> 219.3444 | AE23: 80615.34 | AF23: =AB23/U23 -> 73.853333 | AG23: =AB23/V23 -> 2.8774026 | AH23: =AB23/S23 -> 11.976216 | AI23: 1060 | AJ23: 2D-20127131
A24: Inbound | B24: Vendor to Site | C24: DENALI | D24: WA | E24: LUK2 | F24: OH | G24: 21166451 | H24: 46048 | I24: No | J24: RXONC20O3NUYRHLA26 | K24: 46044 | L24: Yes | M24: 46046 | N24: 46046 | O24: =NETWORKDAYS.INTL(K24,N24,1,$AM$2:$AM$10)-1 -> 1 | P24: Yes | Q24: No | R24: N/A | S24: 2352 | T24: 2D-18059221 2D-17905562 | U24: 14 | V24: 336 | W24: 12000 | X24: FTL | Y24: RXO | Z24: GROUND EXPRESS LLC | AA24: GROUND | AB24: 4877.46 | AC24: =IF(C24="DENALI", AB24*0.495, IF(C24="SCHNEIDER ELECTRIC", AB24*1.136, IF(C24="WWT", AB24*1.2, AC24)))+AB24 -> 7291.8027 | AD24: =AC24-AB24 -> 2414.3427 | AE24: 175329.42 | AF24: =AB24/U24 -> 348.39 | AG24: =AB24/V24 -> 14.51625 | AH24: =AB24/S24 -> 2.07375 | AI24: 1290 | AJ24: 2D-20129254
A25: Inbound | B25: Vendor to Site | C25: SCHNEIDER ELECTRIC | D25: PA | E25: RDU1 | F25: NC | G25: RXO6421540 | H25: 46049 | I25: No | J25: 138903575 | K25: 46045 | L25: Yes | M25: 46050 | N25: 46050 | O25: =NETWORKDAYS.INTL(K25,N25,1,$AM$2:$AM$10)-1 -> 3 | P25: Yes | Q25: No | R25: N/A | S25: 377 | T25: 2D-19648985 | U25: 1 | V25: 7 | W25: 579 | X25: LTL | Y25: RXO | Z25: XPO LOGISTICS | AA25: GROUND | AB25: 188.15 | AC25: =IF(C25="DENALI", AB25*0.495, IF(C25="SCHNEIDER ELECTRIC", AB25*1.136, IF(C25="WWT", AB25*1.2, AC25)))+AB25 -> 401.8884 | AD25: =AC25-AB25 -> 213.7384 | AE25: 3342.43 | AF25: =AB25/U25 -> 188.15 | AG25: =AB25/V25 -> 26.878571 | AH25: =AB25/S25 -> 0.49907162 | AI25: 1290 | AJ25: 2D-18027285
A26: Inbound | B26: Vendor to Site | C26: SCHNEIDER ELECTRIC | D26: PA | E26: MQJ2 | F26: IN | G26: RXO6421835 | H26: 46050 | I26: No | J26: 5055151547 | K26: 46045 | L26: Yes | M26: 46051 | N26: 46051 | O26: =NETWORKDAYS.INTL(K26,N26,1,$AM$2:$AM$10)-1 -> 4 | P26: Yes | Q26: No | R26: N/A | S26: 570 | T26: 2D-20063543 | U26: 1 | V26: 4 | W26: 639 | X26: LTL | Y26: RXO | Z26: PITT OHIO EXPRESS | AA26: GROUND | AB26: 148.91 | AC26: =IF(C26="DENALI", AB26*0.495, IF(C26="SCHNEIDER ELECTRIC", AB26*1.136, IF(C26="WWT", AB26*1.2, AC26)))+AB26 -> 318.07176 | AD26: =AC26-AB26 -> 169.16176 | AE26: 17418.24 | AF26: =AB26/U26 -> 148.91 | AG26: =AB26/V26 -> 37.2275 | AH26: =AB26/S26 -> 0.26124561 | AI26: 1085 | AJ26: 2D-18027278
A27: Inbound | B27: Vendor to RAD | C27: SCHNEIDER ELECTRIC | D27: PA | E27: RAD1 | F27: TN | G27: RXO6450759 | H27: 46052 | I27: No | J27: 0248881909 | K27: 46049 | L27: Yes | M27: 46056 | N27: 46056 | O27: =NETWORKDAYS.INTL(K27,N27,1,$AM$2:$AM$10)-1 -> 5 | P27: Yes | Q27: No | R27: Delivery appt scheduled for 2/3 | S27: 735 | T27: 2D-19972156 | U27: 1 | V27: 3 | W27: 366 | X27: LTL | Y27: RXO | Z27: ESTES EXPRESS LINES | AA27: GROUND | AB27: 214.8 | AC27: =IF(C27="DENALI", AB27*0.495, IF(C27="SCHNEIDER ELECTRIC", AB27*1.136, IF(C27="WWT", AB27*1.2, AC27)))+AB27 -> 458.8128 | AD27: =AC27-AB27 -> 244.0128 | AE27: 10438.64 | AF27: =AB27/U27 -> 214.8 | AG27: =AB27/V27 -> 71.6 | AH27: =AB27/S27 -> 0.2922449 | AI27: 1084 | AJ27: 2D-18027278
A28: Inbound | B28: Vendor to Site | C28: WWT | D28: IL | E28: MQJ9 | F28: IN | G28: RXO6467305 | H28: 46052 | I28: No | J28: 34198815 | K28: 46051 | L28: No | M28: 46052 | N28: 46052 | O28: =NETWORKDAYS.INTL(K28,N28,1,$AM$2:$AM$10)-1 -> 1 | P28: Yes | Q28: No | R28: Original pickup date on 1/28. Dock supervisor rejected truck but didn't realize he was already sent the BOL 3 hours prior. | S28: 275 | T28: 2D-19493807 | U28: 1 | V28: 75 | W28: 235 | X28: LTL | Y28: RXO | Z28: DAYTON FREIGHT LINES | AA28: GROUND | AB28: 144.66 | AC28: =IF(C28="DENALI", AB28*0.495, IF(C28="SCHNEIDER ELECTRIC", AB28*1.136, IF(C28="WWT", AB28*1.2, AC28)))+AB28 -> 318.252 | AD28: =AC28-AB28 -> 173.592 | AE28: 43839.75 | AF28: =AB28/U28 -> 144.66 | AG28: =AB28/V28 -> 1.9288 | AH28: =AB28/S28 -> 0.52603636 | AI28: 1173 | AJ28: 2D-20192827
A29: Inbound | B29: Vendor to RAD | C29: DENALI | D29: IN | E29: RAD1 | F29: TN | G29: RXO6461424 | H29: 46055 | I29: No | J29: 360097986 | K29: 46050 | L29: Yes | M29: 46059 | N29: 46059 | O29: =NETWORKDAYS.INTL(K29,N29,1,$AM$2:$AM$10)-1 -> 7 | P29: Yes | Q29: No | R29: Delivery appt scheduled for 2/2; rescheduled for 2/6 | S29: 441 | T29: 2D-19734426 | U29: 2 | V29: 2 | W29: 760 | X29: LTL | Y29: RXO | Z29: XPO LOGISTICS | AA29: GROUND | AB29: 395.44 | AC29: =IF(C29="DENALI", AB29*0.495, IF(C29="SCHNEIDER ELECTRIC", AB29*1.136, IF(C29="WWT", AB29*1.2, AC29)))+AB29 -> 591.1828 | AD29: =AC29-AB29 -> 195.7428 | AE29: 13567.3 | AF29: =AB29/U29 -> 197.72 | AG29: =AB29/V29 -> 197.72 | AH29: =AB29/S29 -> 0.89668934 | AI29: 1061 | AJ29: 2D-20184532
A30: Inbound | B30: Vendor to Site | C30: DENALI | D30: WA | E30: RIC6 | F30: VA | G30: 21514652 | H30: 46055 | I30: No | J30: RXONC20O11YRIYTA26 | K30: 46051 | L30: Yes | M30: 46056 | N30: 46056 | O30: =NETWORKDAYS.INTL(K30,N30,1,$AM$2:$AM$10)-1 -> 3 | P30: Yes | Q30: No | R30: N/A | S30: 2841 | T30: 2D-17506884 | U30: 2 | V30: 20 | W30: 535 | X30: FTL | Y30: RXO | Z30: BG 011 LLC | AA30: GROUND | AB30: 6500 | AC30: =IF(C30="DENALI", AB30*0.495, IF(C30="SCHNEIDER ELECTRIC", AB30*1.136, IF(C30="WWT", AB30*1.2, AC30)))+AB30 -> 9717.5 | AD30: =AC30-AB30 -> 3217.5 | AE30: 10729.49 | AF30: =AB30/U30 -> 3250 | AG30: =AB30/V30 -> 325 | AH30: =AB30/S30 -> 2.2879268 | AI30: 1290 | AJ30: 2D-20206125
A31: Inbound | B31: Vendor to Site | C31: DENALI | D31: WA | E31: SUT3 | F31: UT | G31: 21508418 | H31: 46055 | I31: No | J31: RXONC20ODCZZ2GSA26 | K31: 46051 | L31: Yes | M31: 46052 | N31: 46052 | O31: =NETWORKDAYS.INTL(K31,N31,1,$AM$2:$AM$10)-1 -> 1 | P31: Yes | Q31: No | R31: N/A | S31: 837 | T31: 2D-19401897 | U31: 10 | V31: 237 | W31: 8500 | X31: FTL | Y31: RXO | Z31: SHOD EXPRESS | AA31: GROUND | AB31: 1921.34 | AC31: =IF(C31="DENALI", AB31*0.495, IF(C31="SCHNEIDER ELECTRIC", AB31*1.136, IF(C31="WWT", AB31*1.2, AC31)))+AB31 -> 2872.4033 | AD31: =AC31-AB31 -> 951.0633 | AE31: 129164.97 | AF31: =AB31/U31 -> 192.134 | AG31: =AB31/V31 -> 8.1069198 | AH31: =AB31/S31 -> 2.2955078 | AI31: 1060 | AJ31: 2D-20198327
A32: Inbound | B32: Vendor to Site | C32: DENALI | D32: IN | E32: DGS3 | F32: SC | G32: RXO6474872 | H32: 46056 | I32: No | J32: 317980666 | K32: 46051 | L32: Yes | M32: 46056 | N32: 46056 | O32: =NETWORKDAYS.INTL(K32,N32,1,$AM$2:$AM$10)-1 -> 3 | P32: Yes | Q32: No | R32: N/A | S32: 640 | T32: 2D-19965883 | U32: 1 | V32: 20 | W32: 350 | X32: LTL | Y32: RXO | Z32: XPO LOGISTICS | AA32: GROUND | AB32: 414.39 | AC32: =IF(C32="DENALI", AB32*0.495, IF(C32="SCHNEIDER ELECTRIC", AB32*1.136, IF(C32="WWT", AB32*1.2, AC32)))+AB32 -> 619.51305 | AD32: =AC32-AB32 -> 205.12305 | AE32: 1855 | AF32: =AB32/U32 -> 414.39 | AG32: =AB32/V32 -> 20.7195 | AH32: =AB32/S32 -> 0.64748438 | AI32: 1172 | AJ32: 2D-20199408
A33: Inbound | B33: Vendor to Site | C33: DENALI | D33: IN | E33: PCW1 | F33: OH | G33: RXO6486130 | H33: 46055 | I33: No | J33: 5055152049 | K33: 46052 | L33: Yes | M33: 46055 | N33: 46055 | O33: =NETWORKDAYS.INTL(K33,N33,1,$AM$2:$AM$10)-1 -> 1 | P33: Yes | Q33: No | R33: N/A | S33: 92 | T33: 2D-20048465 | U33: 1 | V33: 6 | W33: 955 | X33: LTL | Y33: RXO | Z33: PITT OHIO EXPRESS | AA33: GROUND | AB33: 142.88 | AC33: =IF(C33="DENALI", AB33*0.495, IF(C33="SCHNEIDER ELECTRIC", AB33*1.136, IF(C33="WWT", AB33*1.2, AC33)))+AB33 -> 213.6056 | AD33: =AC33-AB33 -> 70.7256 | AE33: 2594.22 | AF33: =AB33/U33 -> 142.88 | AG33: =AB33/V33 -> 23.813333 | AH33: =AB33/S33 -> 1.5530435 | AI33: 1290 | AJ33: 2D-20213194
A34: Inbound | B34: Vendor to Site | C34: DENALI | D34: IN | E34: BDL2 | F34: CT | G34: RXO6494263 | H34: 46057 | I34: No | J34: 317980843 | K34: 46052 | L34: Yes | M34: 46056 | N34: 46056 | O34: =NETWORKDAYS.INTL(K34,N34,1,$AM$2:$AM$10)-1 -> 2 | P34: Yes | Q34: No | R34: Inclement weather near date of delivery | S34: 758 | T34: 2D-19503761 | U34: 1 | V34: 25 | W34: 230 | X34: LTL | Y34: RXO | Z34: XPO LOGISTICS | AA34: GROUND | AB34: 226.9 | AC34: =IF(C34="DENALI", AB34*0.495, IF(C34="SCHNEIDER ELECTRIC", AB34*1.136, IF(C34="WWT", AB34*1.2, AC34)))+AB34 -> 339.2155 | AD34: =AC34-AB34 -> 112.3155 | AE34: 8541.5 | AF34: =AB34/U34 -> 226.9 | AG34: =AB34/V34 -> 9.076 | AH34: =AB34/S34 -> 0.29934037 | AI34: 1290 | AJ34: 2D-20223002
A35: Inbound | B35: Vendor to Site | C35: DENALI | D35: IN | E35: HGR1 | F35: MI | G35: RXO6494400 | H35: 46057 | I35: No | J35: 317980832 | K35: 46052 | L35: Yes | M35: 46055 | N35: 46055 | O35: =NETWORKDAYS.INTL(K35,N35,1,$AM$2:$AM$10)-1 -> 1 | P35: Yes | Q35: No | R35: N/A | S35: 150 | T35: 2D-19682085 | U35: 1 | V35: 25 | W35: 230 | X35: LTL | Y35: RXO | Z35: XPO LOGISTICS | AA35: GROUND | AB35: 160.96 | AC35: =IF(C35="DENALI", AB35*0.495, IF(C35="SCHNEIDER ELECTRIC", AB35*1.136, IF(C35="WWT", AB35*1.2, AC35)))+AB35 -> 240.6352 | AD35: =AC35-AB35 -> 79.6752 | AE35: 8541.5 | AF35: =AB35/U35 -> 160.96 | AG35: =AB35/V35 -> 6.4384 | AH35: =AB35/S35 -> 1.0730667 | AI35: 1290 | AJ35: 27-20223093
A36: Inbound | B36: Vendor to Site | C36: DENALI | D36: IN | E36: AVP9 | F36: PA | G36: RXO6495495 | H36: 46057 | I36: No | J36: 5055151472 | K36: 46052 | L36: Yes | M36: 46055 | N36: 46055 | O36: =NETWORKDAYS.INTL(K36,N36,1,$AM$2:$AM$10)-1 -> 1 | P36: Yes | Q36: No | R36: N/A | S36: 571 | T36: 2D-19679160 | U36: 1 | V36: 1200 | W36: 370 | X36: LTL | Y36: RXO | Z36: PITT OHIO EXPRESS | AA36: GROUND | AB36: 381.77 | AC36: =IF(C36="DENALI", AB36*0.495, IF(C36="SCHNEIDER ELECTRIC", AB36*1.136, IF(C36="WWT", AB36*1.2, AC36)))+AB36 -> 570.74615 | AD36: =AC36-AB36 -> 188.97615 | AE36: 5352 | AF36: =AB36/U36 -> 381.77 | AG36: =AB36/V36 -> 0.31814167 | AH36: =AB36/S36 -> 0.66859895 | AI36: 1085 | AJ36: 2D-20223095
A37: Inbound | B37: Vendor to Site | C37: DENALI | D37: IN | E37: TOL3 | F37: OH | G37: RXO6491697 | H37: 46057 | I37: No | J37: 5055152179 | K37: 46052 | L37: Yes | M37: 46055 | N37: 46055 | O37: =NETWORKDAYS.INTL(K37,N37,1,$AM$2:$AM$10)-1 -> 1 | P37: Yes | Q37: No | R37: N/A | S37: 91 | T37: 2D-19239834 | U37: 1 | V37: 53 | W37: 180 | X37: LTL | Y37: RXO | Z37: PITT OHIO EXPRESS | AA37: GROUND | AB37: 142.88 | AC37: =IF(C37="DENALI", AB37*0.495, IF(C37="SCHNEIDER ELECTRIC", AB37*1.136, IF(C37="WWT", AB37*1.2, AC37)))+AB37 -> 213.6056 | AD37: =AC37-AB37 -> 70.7256 | AE37: 3849.92 | AF37: =AB37/U37 -> 142.88 | AG37: =AB37/V37 -> 2.6958491 | AH37: =AB37/S37 -> 1.5701099 | AI37: 1290 | AJ37: 2D-20215379
A38: Inbound | B38: Vendor to Site | C38: SCHNEIDER ELECTRIC | D38: CA | E38: CAZ5 | F38: CA | G38: RXO6485336 | H38: 46057 | I38: No | J38: 178932191 | K38: 46051 | L38: Yes | M38: 46055 | N38: 46055 | O38: =NETWORKDAYS.INTL(K38,N38,1,$AM$2:$AM$10)-1 -> 2 | P38: Yes | Q38: No | R38: N/A | S38: 47 | T38: 2D-20149971 | U38: 1 | V38: 4 | W38: 327 | X38: LTL | Y38: RXO | Z38: XPO LOGISTICS | AA38: GROUND | AB38: 179.14 | AC38: =IF(C38="DENALI", AB38*0.495, IF(C38="SCHNEIDER ELECTRIC", AB38*1.136, IF(C38="WWT", AB38*1.2, AC38)))+AB38 -> 382.64304 | AD38: =AC38-AB38 -> 203.50304 | AE38: 5617.48 | AF38: =AB38/U38 -> 179.14 | AG38: =AB38/V38 -> 44.785 | AH38: =AB38/S38 -> 3.8114894 | AI38: 1173 | AJ38: 2D-18027278
A39: Inbound | B39: Vendor to Site | C39: SCHNEIDER ELECTRIC | D39: CA | E39: DEN2 | F39: CO | G39: RXO6499620 | H39: 46058 | I39: No | J39: 138916013 | K39: 46052 | L39: Yes | M39: 46057 | N39: 46057 | O39: =NETWORKDAYS.INTL(K39,N39,1,$AM$2:$AM$10)-1 -> 3 | P39: Yes | Q39: No | R39: N/A | S39: 998 | T39: 2D-20181256 | U39: 1 | V39: 10 | W39: 427 | X39: LTL | Y39: RXO | Z39: XPO LOGISTICS | AA39: GROUND | AB39: 266.67 | AC39: =IF(C39="DENALI", AB39*0.495, IF(C39="SCHNEIDER ELECTRIC", AB39*1.136, IF(C39="WWT", AB39*1.2, AC39)))+AB39 -> 569.60712 | AD39: =AC39-AB39 -> 302.93712 | AE39: 5424.7 | AF39: =AB39/U39 -> 266.67 | AG39: =AB39/V39 -> 26.667 | AH39: =AB39/S39 -> 0.26720441 | AI39: 1290 | AJ39: 2D-18027285
A40: Inbound | B40: Vendor to Site | C40: DENALI | D40: WA | E40: RIC6 | F40: VA | G40: 21542751 | H40: 46059 | I40: No | J40: RXONC20OFSOFRJ2B26 | K40: 46055 | L40: Yes | M40: 46058 | N40: 46058 | O40: =NETWORKDAYS.INTL(K40,N40,1,$AM$2:$AM$10)-1 -> 3 | P40: Yes | Q40: No | R40: N/A | S40: 2841 | T40: 2D-17509383 | U40: 24 | V40: 24 | W40: 20400 | X40: FTL | Y40: RXO | Z40: VIS INC | AA40: GROUND | AB40: 7506 | AC40: =IF(C40="DENALI", AB40*0.495, IF(C40="SCHNEIDER ELECTRIC", AB40*1.136, IF(C40="WWT", AB40*1.2, AC40)))+AB40 -> 11221.47 | AD40: =AC40-AB40 -> 3715.47 | AE40: 300000 | AF40: =AB40/U40 -> 312.75 | AG40: =AB40/V40 -> 312.75 | AH40: =AB40/S40 -> 2.6420275 | AI40: 1290 | AJ40: 2D-20241620
...

Sheet 2026 Dashboard
A1: 2026 Global IB Supplier Freight - Dashboard
A2: Auto-updates as shipments are added to the 2026 IB Shipments tab
A4: MONTHLY SUMMARY
A6: Month | B6: Service Cost | C6: Cost Savings | D6: Units | E6: Cargo Value | F6: Shipments | G6: Pallets | H6: Miles | I6: CPU
A7: Jan | B7: =SUMIFS('2026 IB Shipments'!AB$1:AB$2239,'2026 IB Shipments'!K$1:K$2239,">="&DATE(2026,1,1),'2026 IB Shipments'!K$1:K$2239,"<"&DATE(2026,2,1)) -> 31507.73 | C7: =SUMIFS('2026 IB Shipments'!AD$1:AD$2239,'2026 IB Shipments'!K$1:K$2239,">="&DATE(2026,1,1),'2026 IB Shipments'!K$1:K$2239,"<"&DATE(2026,2,1)) -> 19011.16 | D7: =SUMIFS('2026 IB Shipments'!V$1:V$2239,'2026 IB Shipments'!K$1:K$2239,">="&DATE(2026,1,1),'2026 IB Shipments'!K$1:K$2239,"<"&DATE(2026,2,1)) -> 6242 | E7: =SUMIFS('2026 IB Shipments'!AE$1:AE$2239,'2026 IB Shipments'!K$1:K$2239,">="&DATE(2026,1,1),'2026 IB Shipments'!K$1:K$2239,"<"&DATE(2026,2,1)) -> 2052454.3 | F7: =COUNTIFS('2026 IB Shipments'!K$1:K$2239,">="&DATE(2026,1,1),'2026 IB Shipments'!K$1:K$2239,"<"&DATE(2026,2,1)) -> 38 | G7: =SUMIFS('2026 IB Shipments'!U$1:U$2239,'2026 IB Shipments'!K$1:K$2239,">="&DATE(2026,1,1),'2026 IB Shipments'!K$1:K$2239,"<"&DATE(2026,2,1)) -> 95 | H7: =SUMIFS('2026 IB Shipments'!S$1:S$2239,'2026 IB Shipments'!K$1:K$2239,">="&DATE(2026,1,1),'2026 IB Shipments'!K$1:K$2239,"<"&DATE(2026,2,1)) -> 33424 | I7: =IFERROR(B7/D7,"") -> 5.0476979
A8: Feb | B8: =SUMIFS('2026 IB Shipments'!AB$1:AB$2239,'2026 IB Shipments'!K$1:K$2239,">="&DATE(2026,2,1),'2026 IB Shipments'!K$1:K$2239,"<"&DATE(2026,3,1)) -> 91896.22 | C8: =SUMIFS('2026 IB Shipments'!AD$1:AD$2239,'2026 IB Shipments'!K$1:K$2239,">="&DATE(2026,2,1),'2026 IB Shipments'!K$1:K$2239,"<"&DATE(2026,3,1)) -> 48665.88 | D8: =SUMIFS('2026 IB Shipments'!V$1:V$2239,'2026 IB Shipments'!K$1:K$2239,">="&DATE(2026,2,1),'2026 IB Shipments'!K$1:K$2239,"<"&DATE(2026,3,1)) -> 11006 | E8: =SUMIFS('2026 IB Shipments'!AE$1:AE$2239,'2026 IB Shipments'!K$1:K$2239,">="&DATE(2026,2,1),'2026 IB Shipments'!K$1:K$2239,"<"&DATE(2026,3,1)) -> 4586845 | F8: =COUNTIFS('2026 IB Shipments'!K$1:K$2239,">="&DATE(2026,2,1),'2026 IB Shipments'!K$1:K$2239,"<"&DATE(2026,3,1)) -> 58 | G8: =SUMIFS('2026 IB Shipments'!U$1:U$2239,'2026 IB Shipments'!K$1:K$2239,">="&DATE(2026,2,1),'2026 IB Shipments'!K$1:K$2239,"<"&DATE(2026,3,1)) -> 300 | H8: =SUMIFS('2026 IB Shipments'!S$1:S$2239,'2026 IB Shipments'!K$1:K$2239,">="&DATE(2026,2,1),'2026 IB Shipments'!K$1:K$2239,"<"&DATE(2026,3,1)) -> 61153 | I8: =IFERROR(B8/D8,"") -> 8.3496475
A9: Mar | B9: =SUMIFS('2026 IB Shipments'!AB$1:AB$2239,'2026 IB Shipments'!K$1:K$2239,">="&DATE(2026,3,1),'2026 IB Shipments'!K$1:K$2239,"<"&DATE(2026,4,1)) -> 66310.41 | C9: =SUMIFS('2026 IB Shipments'!AD$1:AD$2239,'2026 IB Shipments'!K$1:K$2239,">="&DATE(2026,3,1),'2026 IB Shipments'!K$1:K$2239,"<"&DATE(2026,4,1)) -> 59716.149 | D9: =SUMIFS('2026 IB Shipments'!V$1:V$2239,'2026 IB Shipments'!K$1:K$2239,">="&DATE(2026,3,1),'2026 IB Shipments'!K$1:K$2239,"<"&DATE(2026,4,1)) -> 102423 | E9: =SUMIFS('2026 IB Shipments'!AE$1:AE$2239,'2026 IB Shipments'!K$1:K$2239,">="&DATE(2026,3,1),'2026 IB Shipments'!K$1:K$2239,"<"&DATE(2026,4,1)) -> 8525914.7 | F9: =COUNTIFS('2026 IB Shipments'!K$1:K$2239,">="&DATE(2026,3,1),'2026 IB Shipments'!K$1:K$2239,"<"&DATE(2026,4,1)) -> 89 | G9: =SUMIFS('2026 IB Shipments'!U$1:U$2239,'2026 IB Shipments'!K$1:K$2239,">="&DATE(2026,3,1),'2026 IB Shipments'!K$1:K$2239,"<"&DATE(2026,4,1)) -> 224 | H9: =SUMIFS('2026 IB Shipments'!S$1:S$2239,'2026 IB Shipments'!K$1:K$2239,">="&DATE(2026,3,1),'2026 IB Shipments'!K$1:K$2239,"<"&DATE(2026,4,1)) -> 81295 | I9: =IFERROR(B9/D9,"") -> 0.64741718
A10: Apr | B10: =SUMIFS('2026 IB Shipments'!AB$1:AB$2239,'2026 IB Shipments'!K$1:K$2239,">="&DATE(2026,4,1),'2026 IB Shipments'!K$1:K$2239,"<"&DATE(2026,5,1)) -> 120673.25 | C10: =SUMIFS('2026 IB Shipments'!AD$1:AD$2239,'2026 IB Shipments'!K$1:K$2239,">="&DATE(2026,4,1),'2026 IB Shipments'!K$1:K$2239,"<"&DATE(2026,5,1)) -> 72648.607 | D10: =SUMIFS('2026 IB Shipments'!V$1:V$2239,'2026 IB Shipments'!K$1:K$2239,">="&DATE(2026,4,1),'2026 IB Shipments'!K$1:K$2239,"<"&DATE(2026,5,1)) -> 128203 | E10: =SUMIFS('2026 IB Shipments'!AE$1:AE$2239,'2026 IB Shipments'!K$1:K$2239,">="&DATE(2026,4,1),'2026 IB Shipments'!K$1:K$2239,"<"&DATE(2026,5,1)) -> 13580943 | F10: =COUNTIFS('2026 IB Shipments'!K$1:K$2239,">="&DATE(2026,4,1),'2026 IB Shipments'!K$1:K$2239,"<"&DATE(2026,5,1)) -> 112 | G10: =SUMIFS('2026 IB Shipments'!U$1:U$2239,'2026 IB Shipments'!K$1:K$2239,">="&DATE(2026,4,1),'2026 IB Shipments'!K$1:K$2239,"<"&DATE(2026,5,1)) -> 555 | H10: =SUMIFS('2026 IB Shipments'!S$1:S$2239,'2026 IB Shipments'!K$1:K$2239,">="&DATE(2026,4,1),'2026 IB Shipments'!K$1:K$2239,"<"&DATE(2026,5,1)) -> 120905 | I10: =IFERROR(B10/D10,"") -> 0.94126698
A11: May | B11: =SUMIFS('2026 IB Shipments'!AB$1:AB$2239,'2026 IB Shipments'!K$1:K$2239,">="&DATE(2026,5,1),'2026 IB Shipments'!K$1:K$2239,"<"&DATE(2026,6,1)) -> 104180.99 | C11: =SUMIFS('2026 IB Shipments'!AD$1:AD$2239,'2026 IB Shipments'!K$1:K$2239,">="&DATE(2026,5,1),'2026 IB Shipments'!K$1:K$2239,"<"&DATE(2026,6,1)) -> 54262.796 | D11: =SUMIFS('2026 IB Shipments'!V$1:V$2239,'2026 IB Shipments'!K$1:K$2239,">="&DATE(2026,5,1),'2026 IB Shipments'!K$1:K$2239,"<"&DATE(2026,6,1)) -> 118980 | E11: =SUMIFS('2026 IB Shipments'!AE$1:AE$2239,'2026 IB Shipments'!K$1:K$2239,">="&DATE(2026,5,1),'2026 IB Shipments'!K$1:K$2239,"<"&DATE(2026,6,1)) -> 6710413.9 | F11: =COUNTIFS('2026 IB Shipments'!K$1:K$2239,">="&DATE(2026,5,1),'2026 IB Shipments'!K$1:K$2239,"<"&DATE(2026,6,1)) -> 104 | G11: =SUMIFS('2026 IB Shipments'!U$1:U$2239,'2026 IB Shipments'!K$1:K$2239,">="&DATE(2026,5,1),'2026 IB Shipments'!K$1:K$2239,"<"&DATE(2026,6,1)) -> 394 | H11: =SUMIFS('2026 IB Shipments'!S$1:S$2239,'2026 IB Shipments'!K$1:K$2239,">="&DATE(2026,5,1),'2026 IB Shipments'!K$1:K$2239,"<"&DATE(2026,6,1)) -> 121229.1 | I11: =IFERROR(B11/D11,"") -> 0.87561767
A12: Jun | B12: =SUMIFS('2026 IB Shipments'!AB$1:AB$2239,'2026 IB Shipments'!K$1:K$2239,">="&DATE(2026,6,1),'2026 IB Shipments'!K$1:K$2239,"<"&DATE(2026,7,1)) -> 210263.11 | C12: =SUMIFS('2026 IB Shipments'!AD$1:AD$2239,'2026 IB Shipments'!K$1:K$2239,">="&DATE(2026,6,1),'2026 IB Shipments'!K$1:K$2239,"<"&DATE(2026,7,1)) -> 137277.88 | D12: =SUMIFS('2026 IB Shipments'!V$1:V$2239,'2026 IB Shipments'!K$1:K$2239,">="&DATE(2026,6,1),'2026 IB Shipments'!K$1:K$2239,"<"&DATE(2026,7,1)) -> 123897 | E12: =SUMIFS('2026 IB Shipments'!AE$1:AE$2239,'2026 IB Shipments'!K$1:K$2239,">="&DATE(2026,6,1),'2026 IB Shipments'!K$1:K$2239,"<"&DATE(2026,7,1)) -> 9134237.7 | F12: =COUNTIFS('2026 IB Shipments'!K$1:K$2239,">="&DATE(2026,6,1),'2026 IB Shipments'!K$1:K$2239,"<"&DATE(2026,7,1)) -> 129 | G12: =SUMIFS('2026 IB Shipments'!U$1:U$2239,'2026 IB Shipments'!K$1:K$2239,">="&DATE(2026,6,1),'2026 IB Shipments'!K$1:K$2239,"<"&DATE(2026,7,1)) -> 430 | H12: =SUMIFS('2026 IB Shipments'!S$1:S$2239,'2026 IB Shipments'!K$1:K$2239,">="&DATE(2026,6,1),'2026 IB Shipments'!K$1:K$2239,"<"&DATE(2026,7,1)) -> 154964.9 | I12: =IFERROR(B12/D12,"") -> 1.6970799
A13: Jul | B13: =SUMIFS('2026 IB Shipments'!AB$1:AB$2239,'2026 IB Shipments'!K$1:K$2239,">="&DATE(2026,7,1),'2026 IB Shipments'!K$1:K$2239,"<"&DATE(2026,8,1)) -> 245178.8 | C13: =SUMIFS('2026 IB Shipments'!AD$1:AD$2239,'2026 IB Shipments'!K$1:K$2239,">="&DATE(2026,7,1),'2026 IB Shipments'!K$1:K$2239,"<"&DATE(2026,8,1)) -> 179782.74 | D13: =SUMIFS('2026 IB Shipments'!V$1:V$2239,'2026 IB Shipments'!K$1:K$2239,">="&DATE(2026,7,1),'2026 IB Shipments'!K$1:K$2239,"<"&DATE(2026,8,1)) -> 32066 | E13: =SUMIFS('2026 IB Shipments'!AE$1:AE$2239,'2026 IB Shipments'!K$1:K$2239,">="&DATE(2026,7,1),'2026 IB Shipments'!K$1:K$2239,"<"&DATE(2026,8,1)) -> 12020483 | F13: =COUNTIFS('2026 IB Shipments'!K$1:K$2239,">="&DATE(2026,7,1),'2026 IB Shipments'!K$1:K$2239,"<"&DATE(2026,8,1)) -> 199 | G13: =SUMIFS('2026 IB Shipments'!U$1:U$2239,'2026 IB Shipments'!K$1:K$2239,">="&DATE(2026,7,1),'2026 IB Shipments'!K$1:K$2239,"<"&DATE(2026,8,1)) -> 364 | H13: =SUMIFS('2026 IB Shipments'!S$1:S$2239,'2026 IB Shipments'!K$1:K$2239,">="&DATE(2026,7,1),'2026 IB Shipments'!K$1:K$2239,"<"&DATE(2026,8,1)) -> 207783 | I13: =IFERROR(B13/D13,"") -> 7.6460675
A14: Aug | B14: =SUMIFS('2026 IB Shipments'!AB$1:AB$2239,'2026 IB Shipments'!K$1:K$2239,">="&DATE(2026,8,1),'2026 IB Shipments'!K$1:K$2239,"<"&DATE(2026,9,1)) -> 133991.37 | C14: =SUMIFS('2026 IB Shipments'!AD$1:AD$2239,'2026 IB Shipments'!K$1:K$2239,">="&DATE(2026,8,1),'2026 IB Shipments'!K$1:K$2239,"<"&DATE(2026,9,1)) -> 90808.205 | D14: =SUMIFS('2026 IB Shipments'!V$1:V$2239,'2026 IB Shipments'!K$1:K$2239,">="&DATE(2026,8,1),'2026 IB Shipments'!K$1:K$2239,"<"&DATE(2026,9,1)) -> 121106 | E14: =SUMIFS('2026 IB Shipments'!AE$1:AE$2239,'2026 IB Shipments'!K$1:K$2239,">="&DATE(2026,8,1),'2026 IB Shipments'!K$1:K$2239,"<"&DATE(2026,9,1)) -> 11135096 | F14: =COUNTIFS('2026 IB Shipments'!K$1:K$2239,">="&DATE(2026,8,1),'2026 IB Shipments'!K$1:K$2239,"<"&DATE(2026,9,1)) -> 124 | G14: =SUMIFS('2026 IB Shipments'!U$1:U$2239,'2026 IB Shipments'!K$1:K$2239,">="&DATE(2026,8,1),'2026 IB Shipments'!K$1:K$2239,"<"&DATE(2026,9,1)) -> 322 | H14: =SUMIFS('2026 IB Shipments'!S$1:S$2239,'2026 IB Shipments'!K$1:K$2239,">="&DATE(2026,8,1),'2026 IB Shipments'!K$1:K$2239,"<"&DATE(2026,9,1)) -> 129441.7 | I14: =IFERROR(B14/D14,"") -> 1.1063975
A15: Sep | B15: =SUMIFS('2026 IB Shipments'!AB$1:AB$2239,'2026 IB Shipments'!K$1:K$2239,">="&DATE(2026,9,1),'2026 IB Shipments'!K$1:K$2239,"<"&DATE(2026,10,1)) -> 164559.22 | C15: =SUMIFS('2026 IB Shipments'!AD$1:AD$2239,'2026 IB Shipments'!K$1:K$2239,">="&DATE(2026,9,1),'2026 IB Shipments'!K$1:K$2239,"<"&DATE(2026,10,1)) -> 124575.3 | D15: =SUMIFS('2026 IB Shipments'!V$1:V$2239,'2026 IB Shipments'!K$1:K$2239,">="&DATE(2026,9,1),'2026 IB Shipments'!K$1:K$2239,"<"&DATE(2026,10,1)) -> 176540 | E15: =SUMIFS('2026 IB Shipments'!AE$1:AE$2239,'2026 IB Shipments'!K$1:K$2239,">="&DATE(2026,9,1),'2026 IB Shipments'!K$1:K$2239,"<"&DATE(2026,10,1)) -> 11153945 | F15: =COUNTIFS('2026 IB Shipments'!K$1:K$2239,">="&DATE(2026,9,1),'2026 IB Shipments'!K$1:K$2239,"<"&DATE(2026,10,1)) -> 164 | G15: =SUMIFS('2026 IB Shipments'!U$1:U$2239,'2026 IB Shipments'!K$1:K$2239,">="&DATE(2026,9,1),'2026 IB Shipments'!K$1:K$2239,"<"&DATE(2026,10,1)) -> 349 | H15: =SUMIFS('2026 IB Shipments'!S$1:S$2239,'2026 IB Shipments'!K$1:K$2239,">="&DATE(2026,9,1),'2026 IB Shipments'!K$1:K$2239,"<"&DATE(2026,10,1)) -> 146337.3 | I15: =IFERROR(B15/D15,"") -> 0.93213561
A16: Oct | B16: =SUMIFS('2026 IB Shipments'!AB$1:AB$2239,'2026 IB Shipments'!K$1:K$2239,">="&DATE(2026,10,1),'2026 IB Shipments'!K$1:K$2239,"<"&DATE(2026,11,1)) -> 46293.46 | C16: =SUMIFS('2026 IB Shipments'!AD$1:AD$2239,'2026 IB Shipments'!K$1:K$2239,">="&DATE(2026,10,1),'2026 IB Shipments'!K$1:K$2239,"<"&DATE(2026,11,1)) -> 24668.831 | D16: =SUMIFS('2026 IB Shipments'!V$1:V$2239,'2026 IB Shipments'!K$1:K$2239,">="&DATE(2026,10,1),'2026 IB Shipments'!K$1:K$2239,"<"&DATE(2026,11,1)) -> 124910 | E16: =SUMIFS('2026 IB Shipments'!AE$1:AE$2239,'2026 IB Shipments'!K$1:K$2239,">="&DATE(2026,10,1),'2026 IB Shipments'!K$1:K$2239,"<"&DATE(2026,11,1)) -> 4550482.8 | F16: =COUNTIFS('2026 IB Shipments'!K$1:K$2239,">="&DATE(2026,10,1),'2026 IB Shipments'!K$1:K$2239,"<"&DATE(2026,11,1)) -> 32 | G16: =SUMIFS('2026 IB Shipments'!U$1:U$2239,'2026 IB Shipments'!K$1:K$2239,">="&DATE(2026,10,1),'2026 IB Shipments'!K$1:K$2239,"<"&DATE(2026,11,1)) -> 104 | H16: =SUMIFS('2026 IB Shipments'!S$1:S$2239,'2026 IB Shipments'!K$1:K$2239,">="&DATE(2026,10,1),'2026 IB Shipments'!K$1:K$2239,"<"&DATE(2026,11,1)) -> 31024.1 | I16: =IFERROR(B16/D16,"") -> 0.37061452
A17: Nov | B17: =SUMIFS('2026 IB Shipments'!AB$1:AB$2239,'2026 IB Shipments'!K$1:K$2239,">="&DATE(2026,11,1),'2026 IB Shipments'!K$1:K$2239,"<"&DATE(2026,12,1)) -> 0 | C17: =SUMIFS('2026 IB Shipments'!AD$1:AD$2239,'2026 IB Shipments'!K$1:K$2239,">="&DATE(2026,11,1),'2026 IB Shipments'!K$1:K$2239,"<"&DATE(2026,12,1)) -> 0 | D17: =SUMIFS('2026 IB Shipments'!V$1:V$2239,'2026 IB Shipments'!K$1:K$2239,">="&DATE(2026,11,1),'2026 IB Shipments'!K$1:K$2239,"<"&DATE(2026,12,1)) -> 0 | E17: =SUMIFS('2026 IB Shipments'!AE$1:AE$2239,'2026 IB Shipments'!K$1:K$2239,">="&DATE(2026,11,1),'2026 IB Shipments'!K$1:K$2239,"<"&DATE(2026,12,1)) -> 0 | F17: =COUNTIFS('2026 IB Shipments'!K$1:K$2239,">="&DATE(2026,11,1),'2026 IB Shipments'!K$1:K$2239,"<"&DATE(2026,12,1)) -> 0 | G17: =SUMIFS('2026 IB Shipments'!U$1:U$2239,'2026 IB Shipments'!K$1:K$2239,">="&DATE(2026,11,1),'2026 IB Shipments'!K$1:K$2239,"<"&DATE(2026,12,1)) -> 0 | H17: =SUMIFS('2026 IB Shipments'!S$1:S$2239,'2026 IB Shipments'!K$1:K$2239,">="&DATE(2026,11,1),'2026 IB Shipments'!K$1:K$2239,"<"&DATE(2026,12,1)) -> 0 | I17: =IFERROR(B17/D17,"")
A18: Dec | B18: =SUMIFS('2026 IB Shipments'!AB$1:AB$2239,'2026 IB Shipments'!K$1:K$2239,">="&DATE(2026,12,1),'2026 IB Shipments'!K$1:K$2239,"<"&DATE(2026,13,1)) -> 0 | C18: =SUMIFS('2026 IB Shipments'!AD$1:AD$2239,'2026 IB Shipments'!K$1:K$2239,">="&DATE(2026,12,1),'2026 IB Shipments'!K$1:K$2239,"<"&DATE(2026,13,1)) -> 0 | D18: =SUMIFS('2026 IB Shipments'!V$1:V$2239,'2026 IB Shipments'!K$1:K$2239,">="&DATE(2026,12,1),'2026 IB Shipments'!K$1:K$2239,"<"&DATE(2026,13,1)) -> 0 | E18: =SUMIFS('2026 IB Shipments'!AE$1:AE$2239,'2026 IB Shipments'!K$1:K$2239,">="&DATE(2026,12,1),'2026 IB Shipments'!K$1:K$2239,"<"&DATE(2026,13,1)) -> 0 | F18: =COUNTIFS('2026 IB Shipments'!K$1:K$2239,">="&DATE(2026,12,1),'2026 IB Shipments'!K$1:K$2239,"<"&DATE(2026,13,1)) -> 0 | G18: =SUMIFS('2026 IB Shipments'!U$1:U$2239,'2026 IB Shipments'!K$1:K$2239,">="&DATE(2026,12,1),'2026 IB Shipments'!K$1:K$2239,"<"&DATE(2026,13,1)) -> 0 | H18: =SUMIFS('2026 IB Shipments'!S$1:S$2239,'2026 IB Shipments'!K$1:K$2239,">="&DATE(2026,12,1),'2026 IB Shipments'!K$1:K$2239,"<"&DATE(2026,13,1)) -> 0 | I18: =IFERROR(B18/D18,"")
A19: YTD | B19: =SUM(B7:B18) -> 1214854.6 | C19: =SUM(C7:C18) -> 811417.55 | D19: =SUM(D7:D18) -> 945373 | E19: =SUM(E7:E18) -> 83450816 | F19: =SUM(F7:F18) -> 1049 | G19: =SUM(G7:G18) -> 3137 | H19: =SUM(H7:H18) -> 1087557.1 | I19: =B36 -> 1.2850532
A22: YTD SUMMARY BY SUPPLIER
A24: Supplier | B24: Service Cost | C24: Cost Savings | D24: Units | E24: Cargo Value | F24: Shipments | G24: Pallets
A25: DENALI | B25: =SUMIF('2026 IB Shipments'!C$1:C$2239,"DENALI",'2026 IB Shipments'!AB$1:AB$2239) -> 894056.3 | C25: =SUMIF('2026 IB Shipments'!C$1:C$2239,"DENALI",'2026 IB Shipments'!AD$1:AD$2239) -> 470924.73 | D25: =SUMIF('2026 IB Shipments'!C$1:C$2239,"DENALI",'2026 IB Shipments'!V$1:V$2239) -> 925512 | E25: =SUMIF('2026 IB Shipments'!C$1:C$2239,"DENALI",'2026 IB Shipments'!AE$1:AE$2239) -> 65368834 | F25: =COUNTIF('2026 IB Shipments'!C$1:C$2239,"DENALI") -> 676 | G25: =SUMIF('2026 IB Shipments'!C$1:C$2239,"DENALI",'2026 IB Shipments'!U$1:U$2239) -> 2485
A26: EXPEDITORS | B26: =SUMIF('2026 IB Shipments'!C$1:C$2239,"EXPEDITORS",'2026 IB Shipments'!AB$1:AB$2239) -> 19605 | C26: =SUMIF('2026 IB Shipments'!C$1:C$2239,"EXPEDITORS",'2026 IB Shipments'!AD$1:AD$2239) -> 8095 | D26: =SUMIF('2026 IB Shipments'!C$1:C$2239,"EXPEDITORS",'2026 IB Shipments'!V$1:V$2239) -> 414 | E26: =SUMIF('2026 IB Shipments'!C$1:C$2239,"EXPEDITORS",'2026 IB Shipments'!AE$1:AE$2239) -> 289048.9 | F26: =COUNTIF('2026 IB Shipments'!C$1:C$2239,"EXPEDITORS") -> 3 | G26: =SUMIF('2026 IB Shipments'!C$1:C$2239,"EXPEDITORS",'2026 IB Shipments'!U$1:U$2239) -> 5
A27: SCHNEIDER ELECTRIC | B27: =SUMIF('2026 IB Shipments'!C$1:C$2239,"SCHNEIDER ELECTRIC",'2026 IB Shipments'!AB$1:AB$2239) -> 141208.06 | C27: =SUMIF('2026 IB Shipments'!C$1:C$2239,"SCHNEIDER ELECTRIC",'2026 IB Shipments'!AD$1:AD$2239) -> 160412.36 | D27: =SUMIF('2026 IB Shipments'!C$1:C$2239,"SCHNEIDER ELECTRIC",'2026 IB Shipments'!V$1:V$2239) -> 3490 | E27: =SUMIF('2026 IB Shipments'!C$1:C$2239,"SCHNEIDER ELECTRIC",'2026 IB Shipments'!AE$1:AE$2239) -> 10694253 | F27: =COUNTIF('2026 IB Shipments'!C$1:C$2239,"SCHNEIDER ELECTRIC") -> 305 | G27: =SUMIF('2026 IB Shipments'!C$1:C$2239,"SCHNEIDER ELECTRIC",'2026 IB Shipments'!U$1:U$2239) -> 549
A28: SHI | B28: =SUMIF('2026 IB Shipments'!C$1:C$2239,"SHI",'2026 IB Shipments'!AB$1:AB$2239) -> 69773.4 | C28: =SUMIF('2026 IB Shipments'!C$1:C$2239,"SHI",'2026 IB Shipments'!AD$1:AD$2239) -> 52826.6 | D28: =SUMIF('2026 IB Shipments'!C$1:C$2239,"SHI",'2026 IB Shipments'!V$1:V$2239) -> 3827 | E28: =SUMIF('2026 IB Shipments'!C$1:C$2239,"SHI",'2026 IB Shipments'!AE$1:AE$2239) -> 1737262.4 | F28: =COUNTIF('2026 IB Shipments'!C$1:C$2239,"SHI") -> 15 | G28: =SUMIF('2026 IB Shipments'!C$1:C$2239,"SHI",'2026 IB Shipments'!U$1:U$2239) -> 24
A29: WWT | B29: =SUMIF('2026 IB Shipments'!C$1:C$2239,"WWT",'2026 IB Shipments'!AB$1:AB$2239) -> 9020.8 | C29: =SUMIF('2026 IB Shipments'!C$1:C$2239,"WWT",'2026 IB Shipments'!AD$1:AD$2239) -> 10824.96 | D29: =SUMIF('2026 IB Shipments'!C$1:C$2239,"WWT",'2026 IB Shipments'!V$1:V$2239) -> 11255 | E29: =SUMIF('2026 IB Shipments'!C$1:C$2239,"WWT",'2026 IB Shipments'!AE$1:AE$2239) -> 3450664.1 | F29: =COUNTIF('2026 IB Shipments'!C$1:C$2239,"WWT") -> 32 | G29: =SUMIF('2026 IB Shipments'!C$1:C$2239,"WWT",'2026 IB Shipments'!U$1:U$2239) -> 43
A30: Site Transfer / Launch | B30: =SUMIFS('2026 IB Shipments'!AB$1:AB$2239,'2026 IB Shipments'!B$1:B$2239,"Site Transfer")+SUMIFS('2026 IB Shipments'!AB$1:AB$2239,'2026 IB Shipments'!B$1:B$2239,"Launch") -> 74184 | C30: =SUMIFS('2026 IB Shipments'!AD$1:AD$2239,'2026 IB Shipments'!B$1:B$2239,"Site Transfer")+SUMIFS('2026 IB Shipments'!AD$1:AD$2239,'2026 IB Shipments'!B$1:B$2239,"Launch") -> 104865.44 | D30: =SUMIFS('2026 IB Shipments'!V$1:V$2239,'2026 IB Shipments'!B$1:B$2239,"Site Transfer")+SUMIFS('2026 IB Shipments'!V$1:V$2239,'2026 IB Shipments'!B$1:B$2239,"Launch") -> 835 | E30: =SUMIFS('2026 IB Shipments'!AE$1:AE$2239,'2026 IB Shipments'!B$1:B$2239,"Site Transfer")+SUMIFS('2026 IB Shipments'!AE$1:AE$2239,'2026 IB Shipments'!B$1:B$2239,"Launch") -> 1910753.8 | F30: =COUNTIFS('2026 IB Shipments'!B$1:B$2239,"Site Transfer")+COUNTIFS('2026 IB Shipments'!B$1:B$2239,"Launch") -> 17 | G30: =SUMIFS('2026 IB Shipments'!U$1:U$2239,'2026 IB Shipments'!B$1:B$2239,"Site Transfer")+SUMIFS('2026 IB Shipments'!U$1:U$2239,'2026 IB Shipments'!B$1:B$2239,"Launch") -> 28
A33: YTD CALCULATED METRICS
A35: Metric | B35: YTD Total
A36: CPU (Cost / Unit) | B36: =IFERROR(B19/D19,"") -> 1.2850532
A37: Cost Per Shipment | B37: =IFERROR(B19/F19,"") -> 1158.1073
A38: Cost Per Pallet | B38: =IFERROR(B19/G19,"") -> 387.26636
A39: Cost Per Mile | B39: =IFERROR(B19/H19,"") -> 1.117049
A40: Cost as % of Cargo Value | B40: =IFERROR(B19/E19,"") -> 0.014557731
A41: Total Cost Savings | B41: =C19 -> 811417.55
A42: Savings % | B42: =IFERROR(C19/(B19+C19),"") -> 0.40044846
A45: ADMIN FEE AVOIDANCE (0.5% - Denali Only)
A47: Month | B47: Denali Cargo Value | C47: Admin Fee Avoidance (0.5%)
A48: Jan | B48: =SUMIFS('2026 IB Shipments'!AE$1:AE$2239,'2026 IB Shipments'!C$1:C$2239,"DENALI",'2026 IB Shipments'!K$1:K$2239,">="&DATE(2026,1,1),'2026 IB Shipments'!K$1:K$2239,"<"&DATE(2026,2,1)) -> 1881274.5 | C48: =B48*0.005 -> 9406.3727
A49: Feb | B49: =SUMIFS('2026 IB Shipments'!AE$1:AE$2239,'2026 IB Shipments'!C$1:C$2239,"DENALI",'2026 IB Shipments'!K$1:K$2239,">="&DATE(2026,2,1),'2026 IB Shipments'!K$1:K$2239,"<"&DATE(2026,3,1)) -> 4480411.1 | C49: =B49*0.005 -> 22402.055
A50: Mar | B50: =SUMIFS('2026 IB Shipments'!AE$1:AE$2239,'2026 IB Shipments'!C$1:C$2239,"DENALI",'2026 IB Shipments'!K$1:K$2239,">="&DATE(2026,3,1),'2026 IB Shipments'!K$1:K$2239,"<"&DATE(2026,4,1)) -> 7406281.9 | C50: =B50*0.005 -> 37031.409
A51: Apr | B51: =SUMIFS('2026 IB Shipments'!AE$1:AE$2239,'2026 IB Shipments'!C$1:C$2239,"DENALI",'2026 IB Shipments'!K$1:K$2239,">="&DATE(2026,4,1),'2026 IB Shipments'!K$1:K$2239,"<"&DATE(2026,5,1)) -> 11432827 | C51: =B51*0.005 -> 57164.134
...

Sheet _ChartData
A1: Month | B1: Pickup OT % | C1: Delivery OT % | D1: Shipments
A2: Jan 2026 | B2: 0.92105263 | C2: 0.94736842 | D2: 38
A3: Feb 2026 | B3: 1 | C3: 0.98275862 | D3: 58
A4: Mar 2026 | B4: 0.8988764 | C4: 0.80898876 | D4: 89
A5: Apr 2026 | B5: 0.83035714 | C5: 0.95454545 | D5: 112
A6: May 2026 | B6: 0.89423077 | C6: 0.99038462 | D6: 104
A7: Jun 2026 | B7: 0.90697674 | C7: 0.98412698 | D7: 129
A8: Jul 2026 | B8: 0.88383838 | C8: 0.97461929 | D8: 199
A9: Aug 2026 | B9: 0.87096774 | C9: 0.9516129 | D9: 124
A10: Sep 2026 | B10: 0.85443038 | C10: 0.96062992 | D10: 160

Sheet _BarChartData
A1: Carrier | B1: Pickup OT % | C1: Delivery OT %
A2: XPO LOGISTICS | B2: 0.87015504 | C2: 0.94877049
A3: SAIA MOTOR FREIGHT LINE | B3: 0.85365854 | C3: 0.92682927
A4: DAYTON FREIGHT LINES INC | B4: 0.8 | C4: 0.97058824
A5: PITT OHIO EXPRESS, LLC | B5: 0.88571429 | C5: 1
A6: DAYTON FREIGHT LINES, INC | B6: 0.93103448 | C6: 1
A7: SAIA MOTOR FREIGHT LINES | B7: 1 | C7: 1
A8: PITT OHIO EXPRESS LLC | B8: 0.95454545 | C8: 1
A9: PITT OHIO EXPRESS | B9: 0.94736842 | C9: 0.89473684
A10: DAYTON FREIGHT LINES | B10: 0.75 | C10: 0.9375
A11: SAIA MOTOR FREIGHT LINE, LLC | B11: 0.86666667 | C11: 1
A12: DOHRN TRANSFER COMPANY | B12: 0.61538462 | C12: 1
A13: TFORCE FREIGHT, INC | B13: 0.57142857 | C13: 0.71428571
... A16: TFORCE FREIGHT INC | B16: 0.66666667 | C16: 0.33333333
